Workbook

Sheet Dashboard
A1: Cash Allocation Dashboard — Portfolio Sample | D1: Bucket | E1: Suggested % | F1: Allocation on $10k Check | G1: Notes
A2: Gross Income Used | B2: ='Annual Inputs'!C2 -> 180000 | D2: Labor / subcontractors | E2: =INDEX('Annual Inputs'!$D$8:$D$17,MATCH(D2,'Annual Inputs'!$A$8:$A$17,0)) -> 0.3 | F2: =10000*E2 -> 3000 | G2: Illustrative labor reserve
A3: Total Adjusted Cash Reserves | B3: =SUM('Annual Inputs'!C8:C16) -> 118200 | D3: Auto / truck | E3: =INDEX('Annual Inputs'!$D$8:$D$17,MATCH(D3,'Annual Inputs'!$A$8:$A$17,0)) -> 0.046666667 | F3: =10000*E3 -> 466.66667 | G3: Annual vehicle allowance
A4: Net Profit After SE Tax | B4: ='Annual Inputs'!C5 -> 47700 | D4: Equipment / machines | E4: =INDEX('Annual Inputs'!$D$8:$D$17,MATCH(D4,'Annual Inputs'!$A$8:$A$17,0)) -> 0.066666667 | F4: =10000*E4 -> 666.66667 | G4: Conservative equipment reserve
A5: Self-Employment Tax | B5: ='Annual Inputs'!C4 -> 7800 | D5: Insurance | E5: =INDEX('Annual Inputs'!$D$8:$D$17,MATCH(D5,'Annual Inputs'!$A$8:$A$17,0)) -> 0.05 | F5: =10000*E5 -> 500 | G5: Illustrative insurance reserve
A6: Owner Pay/Profit Allocation | B6: =INDEX('Annual Inputs'!$D$8:$D$17,MATCH("Owner pay/profit",'Annual Inputs'!$A$8:$A$17,0)) -> 0.34333333 | D6: Admin / office | E6: =INDEX('Annual Inputs'!$D$8:$D$17,MATCH(D6,'Annual Inputs'!$A$8:$A$17,0)) -> 0.033333333 | F6: =10000*E6 -> 333.33333 | G6: Administrative and professional costs
A7: Tax Reserve Allocation | B7: =INDEX('Annual Inputs'!$D$8:$D$17,MATCH("Tax reserve",'Annual Inputs'!$A$8:$A$17,0)) -> 0.14 | D7: Supplies / uniforms | E7: =INDEX('Annual Inputs'!$D$8:$D$17,MATCH(D7,'Annual Inputs'!$A$8:$A$17,0)) -> 0 | F7: =10000*E7 -> 0 | G7: Assumed covered separately
D8: Travel / meals | E8: =INDEX('Annual Inputs'!$D$8:$D$17,MATCH(D8,'Annual Inputs'!$A$8:$A$17,0)) -> 0 | F8: =10000*E8 -> 0 | G8: Assumed reimbursed separately
D9: Other / miscellaneous | E9: =INDEX('Annual Inputs'!$D$8:$D$17,MATCH(D9,'Annual Inputs'!$A$8:$A$17,0)) -> 0.02 | F9: =10000*E9 -> 200 | G9: Contingency reserve
D10: Tax reserve | E10: =INDEX('Annual Inputs'!$D$8:$D$17,MATCH(D10,'Annual Inputs'!$A$8:$A$17,0)) -> 0.14 | F10: =10000*E10 -> 1400 | G10: Illustrative tax reserve
D11: Owner pay/profit | E11: =INDEX('Annual Inputs'!$D$8:$D$17,MATCH(D11,'Annual Inputs'!$A$8:$A$17,0)) -> 0.34333333 | F11: =10000*E11 -> 3433.3333 | G11: Formula-driven remainder

Sheet Annual Inputs
A1: Source / Item | B1: Sample Annual Amount | C1: Cash-Flow Adjusted Amount | D1: % of Gross | E1: Notes
A2: Gross Income Used | B2: 180000 | C2: 180000 | D2: =C2/$C$2 -> 1 | E2: Fictional gross receipts used for portfolio demonstration.
A3: Total Schedule C Expenses | B3: 124500 | C3: 124500 | D3: =C3/$C$2 -> 0.69166667 | E3: Sample expense baseline; not all expenses require equal cash reserves.
A4: Self-Employment Tax | B4: 7800 | C4: 7800 | D4: =C4/$C$2 -> 0.043333333 | E4: Illustrative self-employment tax input.
A5: Net Profit After SE Tax | B5: 55500 | C5: 47700 | D5: =C5/$C$2 -> 0.265 | E5: Sample operating profit less the tax input.
A7: Bucket | B7: Sample Annual Amount | C7: Cash Allocation Amount | D7: Allocation % | E7: Treatment / Notes
A8: Labor / subcontractors | B8: 54000 | C8: 54000 | D8: =C8/$C$2 -> 0.3 | E8: Illustrative subcontractor reserve.
A9: Auto / truck | B9: 24000 | C9: 8400 | D9: =C9/$C$2 -> 0.046666667 | E9: Annual vehicle operating allowance.
A10: Equipment / machines | B10: 18000 | C10: 12000 | D10: =C10/$C$2 -> 0.066666667 | E10: Conservative equipment and maintenance reserve.
A11: Insurance | B11: 9000 | C11: 9000 | D11: =C11/$C$2 -> 0.05 | E11: Illustrative insurance reserve.
A12: Admin / office | B12: 6000 | C12: 6000 | D12: =C12/$C$2 -> 0.033333333 | E12: Administrative, professional, phone, and office costs.
A13: Supplies / uniforms | B13: 3500 | C13: 0 | D13: =C13/$C$2 -> 0 | E13: Assumed covered under the prime contract.
A14: Travel / meals | B14: 4500 | C14: 0 | D14: =C14/$C$2 -> 0 | E14: Assumed reimbursed or covered separately.
A15: Other / miscellaneous | B15: 5500 | C15: 3600 | D15: =C15/$C$2 -> 0.02 | E15: Contingency and miscellaneous operating reserve.
A16: Tax reserve | B16: 7800 | C16: 25200 | D16: =C16/$C$2 -> 0.14 | E16: Illustrative 14% planning reserve.
A17: Owner pay/profit | B17: 51536 | C17: =MAX(0,$C$2-SUM($C$8:$C$16)) -> 61800 | D17: =C17/$C$2 -> 0.34333333 | E17: Formula-driven remainder after adjusted reserves.

Sheet Check Allocator
A1: Check Allocator
A2: Check amount | B2: 12500
A3: Pass-through / reimbursed amount included in check | B3: 500 | D3: Exclude pass-through materials and reimbursements before allocating operating cash.
A4: Allocatable income | B4: =MAX(0,B2-B3) -> 12000
A5: Weekly labor/pay need | B5: 1800
A6: Weeks to protect | B6: 2
A7: Required labor reserve | B7: =B5*B6 -> 3600
A8: Labor method | B8: Use greater of % or reserve
A10: Bucket | B10: Allocation % | C10: Percent-Based Amount | D10: Minimum Reserve | E10: Final Allocation | F10: Notes
A11: Labor / subcontractors | B11: =INDEX('Annual Inputs'!$D$8:$D$17,MATCH(A11,'Annual Inputs'!$A$8:$A$17,0))+5% -> 0.35 | C11: =$B$4*B11 -> 4200 | D11: =$B$7 -> 3600 | E11: =MAX(C11,D11) -> 4200 | F11: Uses the greater of the percentage allocation or the protected labor reserve.
A12: Auto / truck | B12: =INDEX('Annual Inputs'!$D$8:$D$17,MATCH(A12,'Annual Inputs'!$A$8:$A$17,0)) -> 0.046666667 | C12: =$B$4*B12 -> 560 | D12: 0 | E12: =C12 -> 560 | F12: Vehicle operating allowance.
A13: Equipment / machines | B13: =INDEX('Annual Inputs'!$D$8:$D$17,MATCH(A13,'Annual Inputs'!$A$8:$A$17,0)) -> 0.066666667 | C13: =$B$4*B13 -> 800 | D13: 0 | E13: =C13 -> 800 | F13: Equipment and maintenance reserve.
A14: Insurance | B14: =INDEX('Annual Inputs'!$D$8:$D$17,MATCH(A14,'Annual Inputs'!$A$8:$A$17,0)) -> 0.05 | C14: =$B$4*B14 -> 600 | D14: 0 | E14: =C14 -> 600 | F14: Insurance reserve can be adjusted when covered elsewhere.
A15: Admin / office | B15: =INDEX('Annual Inputs'!$D$8:$D$17,MATCH(A15,'Annual Inputs'!$A$8:$A$17,0)) -> 0.033333333 | C15: =$B$4*B15 -> 400 | D15: 0 | E15: =C15 -> 400 | F15: Administrative and professional costs.
A16: Supplies / uniforms | B16: =INDEX('Annual Inputs'!$D$8:$D$17,MATCH(A16,'Annual Inputs'!$A$8:$A$17,0)) -> 0 | C16: =$B$4*B16 -> 0 | D16: 0 | E16: =C16 -> 0 | F16: Assumed covered separately.
A17: Travel / meals | B17: =INDEX('Annual Inputs'!$D$8:$D$17,MATCH(A17,'Annual Inputs'!$A$8:$A$17,0)) -> 0 | C17: =$B$4*B17 -> 0 | D17: 0 | E17: =C17 -> 0 | F17: Assumed reimbursed or covered separately.
A18: Other / miscellaneous | B18: =INDEX('Annual Inputs'!$D$8:$D$17,MATCH(A18,'Annual Inputs'!$A$8:$A$17,0)) -> 0.02 | C18: =$B$4*B18 -> 240 | D18: 0 | E18: =C18 -> 240 | F18: Contingency reserve.
A19: Tax reserve | B19: =INDEX('Annual Inputs'!$D$8:$D$17,MATCH(A19,'Annual Inputs'!$A$8:$A$17,0)) -> 0.14 | C19: =$B$4*B19 -> 1680 | D19: 0 | E19: =C19 -> 1680 | F19: Conservative tax planning reserve.
A20: Owner pay/profit | B20: =MAX(0,1-SUM(B11:B19)) -> 0.29333333 | C20: =$B$4*B20 -> 3520 | D20: 0 | E20: =MAX(0,$B$4-SUM(E11:E19)) -> 3520 | F20: Formula-driven remainder after reserves.
A22: Total allocated | E22: =SUM(E11:E20) -> 12000
A23: Unallocated / shortage | E23: =$B$4-E22 -> 0 | F23: Negative means reserve targets exceed this check

Sheet Spending Tracker
A1: Pay-Period Cash Allocation & Annual Projection
A2: Enter usable income and tax reserve for each semi-monthly pay period. Fictional sample values reflect seasonal work volume correlated with estimated temperature; projection = average filled amount × 24 pays. | G2: =D2-F2 -> 0
A4: Summary | D4: Projected annual usable income | G4: Projected annual taxes
A5: Latest filled pay # | B5: =IFERROR(LOOKUP(2,1/((C10:C33<>"")+(D10:D33<>"")>0),A10:A33),0) -> 12 | D5: Average usable per pay | E5: =IFERROR(SUM(C10:C33)/COUNT(C10:C33)*24,0) -> 73540 | G5: Average tax reserve per pay | H5: =IFERROR(SUM(D10:D33)/COUNT(D10:D33)*24,0) -> 28360
A6: Projected annual total | B6: =E5+H5 -> 101900 | E6: =IFERROR(AVERAGE(C10:C33),0) -> 3064.1667 | H6: =IFERROR(AVERAGE(D10:D33),0) -> 1181.6667
A9: Pay Period # | B9: Pay Date | C9: Usable Income | D9: Tax Reserve | E9: Total Recorded | F9: Usable YTD | G9: Projected Annual Usable Income | H9: Tax YTD | I9: Projected Annual Taxes | J9: Projected Annual Total
A10: 1 | B10: 46029 | C10: 1475 | D10: 575 | E10: =IF(COUNTA(C10:D10)=0,"",N(C10)+N(D10)) -> 2050 | F10: =IF(COUNTA($C$10:C10)=0,"",SUM($C$10:C10)) -> 1475 | G10: =IF(COUNT($C$10:C10)=0,"",AVERAGE($C$10:C10)*24) -> 35400 | H10: =IF(COUNTA($D$10:D10)=0,"",SUM($D$10:D10)) -> 575 | I10: =IF(COUNT($D$10:D10)=0,"",AVERAGE($D$10:D10)*24) -> 13800 | J10: =IF(COUNTA(G10:I10)=0,"",N(G10)+N(I10)) -> 49200
A11: 2 | B11: 46044 | C11: 1730 | D11: 670 | E11: =IF(COUNTA(C11:D11)=0,"",N(C11)+N(D11)) -> 2400 | F11: =IF(COUNTA($C$10:C11)=0,"",SUM($C$10:C11)) -> 3205 | G11: =IF(COUNT($C$10:C11)=0,"",AVERAGE($C$10:C11)*24) -> 38460 | H11: =IF(COUNTA($D$10:D11)=0,"",SUM($D$10:D11)) -> 1245 | I11: =IF(COUNT($D$10:D11)=0,"",AVERAGE($D$10:D11)*24) -> 14940 | J11: =IF(COUNTA(G11:I11)=0,"",N(G11)+N(I11)) -> 53400
A12: 3 | B12: 46060 | C12: 2160 | D12: 840 | E12: =IF(COUNTA(C12:D12)=0,"",N(C12)+N(D12)) -> 3000 | F12: =IF(COUNTA($C$10:C12)=0,"",SUM($C$10:C12)) -> 5365 | G12: =IF(COUNT($C$10:C12)=0,"",AVERAGE($C$10:C12)*24) -> 42920 | H12: =IF(COUNTA($D$10:D12)=0,"",SUM($D$10:D12)) -> 2085 | I12: =IF(COUNT($D$10:D12)=0,"",AVERAGE($D$10:D12)*24) -> 16680 | J12: =IF(COUNTA(G12:I12)=0,"",N(G12)+N(I12)) -> 59600
A13: 4 | B13: 46075 | C13: 2210 | D13: 740 | E13: =IF(COUNTA(C13:D13)=0,"",N(C13)+N(D13)) -> 2950 | F13: =IF(COUNTA($C$10:C13)=0,"",SUM($C$10:C13)) -> 7575 | G13: =IF(COUNT($C$10:C13)=0,"",AVERAGE($C$10:C13)*24) -> 45450 | H13: =IF(COUNTA($D$10:D13)=0,"",SUM($D$10:D13)) -> 2825 | I13: =IF(COUNT($D$10:D13)=0,"",AVERAGE($D$10:D13)*24) -> 16950 | J13: =IF(COUNTA(G13:I13)=0,"",N(G13)+N(I13)) -> 62400
A14: 5 | B14: 46088 | C14: 2810 | D14: 1090 | E14: =IF(COUNTA(C14:D14)=0,"",N(C14)+N(D14)) -> 3900 | F14: =IF(COUNTA($C$10:C14)=0,"",SUM($C$10:C14)) -> 10385 | G14: =IF(COUNT($C$10:C14)=0,"",AVERAGE($C$10:C14)*24) -> 49848 | H14: =IF(COUNTA($D$10:D14)=0,"",SUM($D$10:D14)) -> 3915 | I14: =IF(COUNT($D$10:D14)=0,"",AVERAGE($D$10:D14)*24) -> 18792 | J14: =IF(COUNTA(G14:I14)=0,"",N(G14)+N(I14)) -> 68640
A15: 6 | B15: 46103 | C15: 3095 | D15: 1205 | E15: =IF(COUNTA(C15:D15)=0,"",N(C15)+N(D15)) -> 4300 | F15: =IF(COUNTA($C$10:C15)=0,"",SUM($C$10:C15)) -> 13480 | G15: =IF(COUNT($C$10:C15)=0,"",AVERAGE($C$10:C15)*24) -> 53920 | H15: =IF(COUNTA($D$10:D15)=0,"",SUM($D$10:D15)) -> 5120 | I15: =IF(COUNT($D$10:D15)=0,"",AVERAGE($D$10:D15)*24) -> 20480 | J15: =IF(COUNTA(G15:I15)=0,"",N(G15)+N(I15)) -> 74400
A16: 7 | B16: 46119 | C16: 3275 | D16: 1275 | E16: =IF(COUNTA(C16:D16)=0,"",N(C16)+N(D16)) -> 4550 | F16: =IF(COUNTA($C$10:C16)=0,"",SUM($C$10:C16)) -> 16755 | G16: =IF(COUNT($C$10:C16)=0,"",AVERAGE($C$10:C16)*24) -> 57445.714 | H16: =IF(COUNTA($D$10:D16)=0,"",SUM($D$10:D16)) -> 6395 | I16: =IF(COUNT($D$10:D16)=0,"",AVERAGE($D$10:D16)*24) -> 21925.714 | J16: =IF(COUNTA(G16:I16)=0,"",N(G16)+N(I16)) -> 79371.429
A17: 8 | B17: 46134 | C17: 3600 | D17: 1400 | E17: =IF(COUNTA(C17:D17)=0,"",N(C17)+N(D17)) -> 5000 | F17: =IF(COUNTA($C$10:C17)=0,"",SUM($C$10:C17)) -> 20355 | G17: =IF(COUNT($C$10:C17)=0,"",AVERAGE($C$10:C17)*24) -> 61065 | H17: =IF(COUNTA($D$10:D17)=0,"",SUM($D$10:D17)) -> 7795 | I17: =IF(COUNT($D$10:D17)=0,"",AVERAGE($D$10:D17)*24) -> 23385 | J17: =IF(COUNTA(G17:I17)=0,"",N(G17)+N(I17)) -> 84450
A18: 9 | B18: 46149 | C18: 3780 | D18: 1470 | E18: =IF(COUNTA(C18:D18)=0,"",N(C18)+N(D18)) -> 5250 | F18: =IF(COUNTA($C$10:C18)=0,"",SUM($C$10:C18)) -> 24135 | G18: =IF(COUNT($C$10:C18)=0,"",AVERAGE($C$10:C18)*24) -> 64360 | H18: =IF(COUNTA($D$10:D18)=0,"",SUM($D$10:D18)) -> 9265 | I18: =IF(COUNT($D$10:D18)=0,"",AVERAGE($D$10:D18)*24) -> 24706.667 | J18: =IF(COUNTA(G18:I18)=0,"",N(G18)+N(I18)) -> 89066.667
A19: 10 | B19: 46164 | C19: 4030 | D19: 1570 | E19: =IF(COUNTA(C19:D19)=0,"",N(C19)+N(D19)) -> 5600 | F19: =IF(COUNTA($C$10:C19)=0,"",SUM($C$10:C19)) -> 28165 | G19: =IF(COUNT($C$10:C19)=0,"",AVERAGE($C$10:C19)*24) -> 67596 | H19: =IF(COUNTA($D$10:D19)=0,"",SUM($D$10:D19)) -> 10835 | I19: =IF(COUNT($D$10:D19)=0,"",AVERAGE($D$10:D19)*24) -> 26004 | J19: =IF(COUNTA(G19:I19)=0,"",N(G19)+N(I19)) -> 93600
A20: 11 | B20: 46180 | C20: 4175 | D20: 1625 | E20: =IF(COUNTA(C20:D20)=0,"",N(C20)+N(D20)) -> 5800 | F20: =IF(COUNTA($C$10:C20)=0,"",SUM($C$10:C20)) -> 32340 | G20: =IF(COUNT($C$10:C20)=0,"",AVERAGE($C$10:C20)*24) -> 70560 | H20: =IF(COUNTA($D$10:D20)=0,"",SUM($D$10:D20)) -> 12460 | I20: =IF(COUNT($D$10:D20)=0,"",AVERAGE($D$10:D20)*24) -> 27185.455 | J20: =IF(COUNTA(G20:I20)=0,"",N(G20)+N(I20)) -> 97745.455
A21: 12 | B21: 46195 | C21: 4430 | D21: 1720 | E21: =IF(COUNTA(C21:D21)=0,"",N(C21)+N(D21)) -> 6150 | F21: =IF(COUNTA($C$10:C21)=0,"",SUM($C$10:C21)) -> 36770 | G21: =IF(COUNT($C$10:C21)=0,"",AVERAGE($C$10:C21)*24) -> 73540 | H21: =IF(COUNTA($D$10:D21)=0,"",SUM($D$10:D21)) -> 14180 | I21: =IF(COUNT($D$10:D21)=0,"",AVERAGE($D$10:D21)*24) -> 28360 | J21: =IF(COUNTA(G21:I21)=0,"",N(G21)+N(I21)) -> 101900
A22: 13 | B22: 46210 | E22: =IF(COUNTA(C22:D22)=0,"",N(C22)+N(D22)) | F22: =IF(COUNTA($C$10:C22)=0,"",SUM($C$10:C22)) -> 36770 | G22: =IF(COUNT($C$10:C22)=0,"",AVERAGE($C$10:C22)*24) -> 73540 | H22: =IF(COUNTA($D$10:D22)=0,"",SUM($D$10:D22)) -> 14180 | I22: =IF(COUNT($D$10:D22)=0,"",AVERAGE($D$10:D22)*24) -> 28360 | J22: =IF(COUNTA(G22:I22)=0,"",N(G22)+N(I22)) -> 101900
A23: 14 | B23: 46225 | E23: =IF(COUNTA(C23:D23)=0,"",N(C23)+N(D23)) | F23: =IF(COUNTA($C$10:C23)=0,"",SUM($C$10:C23)) -> 36770 | G23: =IF(COUNT($C$10:C23)=0,"",AVERAGE($C$10:C23)*24) -> 73540 | H23: =IF(COUNTA($D$10:D23)=0,"",SUM($D$10:D23)) -> 14180 | I23: =IF(COUNT($D$10:D23)=0,"",AVERAGE($D$10:D23)*24) -> 28360 | J23: =IF(COUNTA(G23:I23)=0,"",N(G23)+N(I23)) -> 101900
A24: 15 | B24: 46241 | E24: =IF(COUNTA(C24:D24)=0,"",N(C24)+N(D24)) | F24: =IF(COUNTA($C$10:C24)=0,"",SUM($C$10:C24)) -> 36770 | G24: =IF(COUNT($C$10:C24)=0,"",AVERAGE($C$10:C24)*24) -> 73540 | H24: =IF(COUNTA($D$10:D24)=0,"",SUM($D$10:D24)) -> 14180 | I24: =IF(COUNT($D$10:D24)=0,"",AVERAGE($D$10:D24)*24) -> 28360 | J24: =IF(COUNTA(G24:I24)=0,"",N(G24)+N(I24)) -> 101900
A25: 16 | B25: 46256 | E25: =IF(COUNTA(C25:D25)=0,"",N(C25)+N(D25)) | F25: =IF(COUNTA($C$10:C25)=0,"",SUM($C$10:C25)) -> 36770 | G25: =IF(COUNT($C$10:C25)=0,"",AVERAGE($C$10:C25)*24) -> 73540 | H25: =IF(COUNTA($D$10:D25)=0,"",SUM($D$10:D25)) -> 14180 | I25: =IF(COUNT($D$10:D25)=0,"",AVERAGE($D$10:D25)*24) -> 28360 | J25: =IF(COUNTA(G25:I25)=0,"",N(G25)+N(I25)) -> 101900
A26: 17 | B26: 46272 | E26: =IF(COUNTA(C26:D26)=0,"",N(C26)+N(D26)) | F26: =IF(COUNTA($C$10:C26)=0,"",SUM($C$10:C26)) -> 36770 | G26: =IF(COUNT($C$10:C26)=0,"",AVERAGE($C$10:C26)*24) -> 73540 | H26: =IF(COUNTA($D$10:D26)=0,"",SUM($D$10:D26)) -> 14180 | I26: =IF(COUNT($D$10:D26)=0,"",AVERAGE($D$10:D26)*24) -> 28360 | J26: =IF(COUNTA(G26:I26)=0,"",N(G26)+N(I26)) -> 101900
A27: 18 | B27: 46287 | E27: =IF(COUNTA(C27:D27)=0,"",N(C27)+N(D27)) | F27: =IF(COUNTA($C$10:C27)=0,"",SUM($C$10:C27)) -> 36770 | G27: =IF(COUNT($C$10:C27)=0,"",AVERAGE($C$10:C27)*24) -> 73540 | H27: =IF(COUNTA($D$10:D27)=0,"",SUM($D$10:D27)) -> 14180 | I27: =IF(COUNT($D$10:D27)=0,"",AVERAGE($D$10:D27)*24) -> 28360 | J27: =IF(COUNTA(G27:I27)=0,"",N(G27)+N(I27)) -> 101900
A28: 19 | B28: 46302 | E28: =IF(COUNTA(C28:D28)=0,"",N(C28)+N(D28)) | F28: =IF(COUNTA($C$10:C28)=0,"",SUM($C$10:C28)) -> 36770 | G28: =IF(COUNT($C$10:C28)=0,"",AVERAGE($C$10:C28)*24) -> 73540 | H28: =IF(COUNTA($D$10:D28)=0,"",SUM($D$10:D28)) -> 14180 | I28: =IF(COUNT($D$10:D28)=0,"",AVERAGE($D$10:D28)*24) -> 28360 | J28: =IF(COUNTA(G28:I28)=0,"",N(G28)+N(I28)) -> 101900
A29: 20 | B29: 46317 | E29: =IF(COUNTA(C29:D29)=0,"",N(C29)+N(D29)) | F29: =IF(COUNTA($C$10:C29)=0,"",SUM($C$10:C29)) -> 36770 | G29: =IF(COUNT($C$10:C29)=0,"",AVERAGE($C$10:C29)*24) -> 73540 | H29: =IF(COUNTA($D$10:D29)=0,"",SUM($D$10:D29)) -> 14180 | I29: =IF(COUNT($D$10:D29)=0,"",AVERAGE($D$10:D29)*24) -> 28360 | J29: =IF(COUNTA(G29:I29)=0,"",N(G29)+N(I29)) -> 101900
A30: 21 | B30: 46333 | E30: =IF(COUNTA(C30:D30)=0,"",N(C30)+N(D30)) | F30: =IF(COUNTA($C$10:C30)=0,"",SUM($C$10:C30)) -> 36770 | G30: =IF(COUNT($C$10:C30)=0,"",AVERAGE($C$10:C30)*24) -> 73540 | H30: =IF(COUNTA($D$10:D30)=0,"",SUM($D$10:D30)) -> 14180 | I30: =IF(COUNT($D$10:D30)=0,"",AVERAGE($D$10:D30)*24) -> 28360 | J30: =IF(COUNTA(G30:I30)=0,"",N(G30)+N(I30)) -> 101900
A31: 22 | B31: 46348 | E31: =IF(COUNTA(C31:D31)=0,"",N(C31)+N(D31)) | F31: =IF(COUNTA($C$10:C31)=0,"",SUM($C$10:C31)) -> 36770 | G31: =IF(COUNT($C$10:C31)=0,"",AVERAGE($C$10:C31)*24) -> 73540 | H31: =IF(COUNTA($D$10:D31)=0,"",SUM($D$10:D31)) -> 14180 | I31: =IF(COUNT($D$10:D31)=0,"",AVERAGE($D$10:D31)*24) -> 28360 | J31: =IF(COUNTA(G31:I31)=0,"",N(G31)+N(I31)) -> 101900
A32: 23 | B32: 46363 | E32: =IF(COUNTA(C32:D32)=0,"",N(C32)+N(D32)) | F32: =IF(COUNTA($C$10:C32)=0,"",SUM($C$10:C32)) -> 36770 | G32: =IF(COUNT($C$10:C32)=0,"",AVERAGE($C$10:C32)*24) -> 73540 | H32: =IF(COUNTA($D$10:D32)=0,"",SUM($D$10:D32)) -> 14180 | I32: =IF(COUNT($D$10:D32)=0,"",AVERAGE($D$10:D32)*24) -> 28360 | J32: =IF(COUNTA(G32:I32)=0,"",N(G32)+N(I32)) -> 101900
A33: 24 | B33: 46378 | E33: =IF(COUNTA(C33:D33)=0,"",N(C33)+N(D33)) | F33: =IF(COUNTA($C$10:C33)=0,"",SUM($C$10:C33)) -> 36770 | G33: =IF(COUNT($C$10:C33)=0,"",AVERAGE($C$10:C33)*24) -> 73540 | H33: =IF(COUNTA($D$10:D33)=0,"",SUM($D$10:D33)) -> 14180 | I33: =IF(COUNT($D$10:D33)=0,"",AVERAGE($D$10:D33)*24) -> 28360 | J33: =IF(COUNTA(G33:I33)=0,"",N(G33)+N(I33)) -> 101900
A35: Notes / How to use
A36: 1 | B36: Enter usable income from each semi-monthly payment in column C.
A37: 2 | B37: Enter the tax reserve set aside from that same payment in column D.
A38: 3 | B38: Projected annual income = average of filled pay periods × 24.
A39: 4 | B39: Exclude reimbursed or pass-through funds before entering usable income or tax reserve.
A40: 5 | B40: Leave future pay periods blank; enter $0 only when the actual amount is zero.
A42: Pay Period # | B42: Pay Date | C42: Estimated Avg Temp (°F) | D42: Season / Work Note | F42: Notes
A43: 1 | B43: 46029 | C43: 43 | D43: Cold / slow season risk | F43: Notes | G43: Fictional portfolio values model positive seasonal correlation between temperature and construction income.
A44: 2 | B44: 46044 | C44: 44 | D44: Cold / slow season risk
A45: 3 | B45: 46060 | C45: 47 | D45: Cold / slow season risk | F45: Source type | G45: NOAA/NCEI U.S. Climate Normals 1991–2020
...

Sheet Lists
A1: Categories | C1: Yes/No
A2: Labor / subcontractors | C2: Yes
A3: Auto / truck | C3: No
A4: Equipment / machines
A5: Insurance
A6: Admin / office
A7: Supplies / uniforms
A8: Travel / meals
A9: Other / miscellaneous
A10: Tax reserve
A11: Owner pay/profit
A12: Pass-through / reimbursed
